<?xml version="1.0"?>
<robot name="robotic_arm">

    <!-- Base -->
    <link name="base">
        <visual>
            <geometry><cylinder radius="0.12" length="0.05"/></geometry>
        </visual>
        <collision>
            <geometry><cylinder radius="0.12" length="0.05"/></geometry>
        </collision>
        <inertial>
            <mass value="5"/>
            <inertia ixx="0.2" iyy="0.2" izz="0.2" ixy="0" ixz="0" iyz="0"/>
        </inertial>
    </link>

    <!-- Arm Base -->
    <link name="arm_base">
        <visual>
            <geometry><cylinder radius="0.1" length="0.1"/></geometry>
        </visual>
        <collision>
            <geometry><cylinder radius="0.1" length="0.1"/></geometry>
        </collision>
        <inertial>
            <mass value="3"/>
            <inertia ixx="0.1" iyy="0.1" izz="0.1" ixy="0" ixz="0" iyz="0"/>
        </inertial>
    </link>

    <joint name="base_to_arm" type="revolute">
        <parent link="base"/>
        <child link="arm_base"/>
        <origin xyz="0 0 0.1"/>
        <axis xyz="0 1 0"/>
        <limit lower="-1.57" upper="1.57" effort="100" velocity="1.0"/>
    </joint>

    <!-- Arm Link 1 -->
    <link name="arm_link1">
        <visual>
            <geometry><box size="0.1 0.1 0.4"/></geometry>
        </visual>
        <collision>
            <geometry><box size="0.1 0.1 0.4"/></geometry>
        </collision>
        <inertial>
            <mass value="2"/>
            <inertia ixx="0.05" iyy="0.05" izz="0.05" ixy="0" ixz="0" iyz="0"/>
        </inertial>
    </link>

    <joint name="arm_joint1" type="revolute">
        <parent link="arm_base"/>
        <child link="arm_link1"/>
        <origin xyz="0 0 0.1"/>
        <axis xyz="0 1 0"/>
        <limit lower="-1.57" upper="1.57"/>
    </joint>

    <!-- Arm Link 2 -->
    <link name="arm_link2">
        <visual>
            <geometry><box size="0.1 0.1 0.4"/></geometry>
        </visual>
        <collision>
            <geometry><box size="0.1 0.1 0.4"/></geometry>
        </collision>
        <inertial>
            <mass value="1.5"/>
            <inertia ixx="0.04" iyy="0.04" izz="0.04" ixy="0" ixz="0" iyz="0"/>
        </inertial>
    </link>

    <joint name="arm_joint2" type="revolute">
        <parent link="arm_link1"/>
        <child link="arm_link2"/>
        <origin xyz="0 0 0.4"/>
        <axis xyz="0 1 0"/>
        <limit lower="-1.57" upper="1.57"/>
    </joint>

    <!-- Arm Link 3 -->
    <link name="arm_link3">
        <visual>
            <geometry><box size="0.1 0.1 0.3"/></geometry>
        </visual>
        <collision>
            <geometry><box size="0.1 0.1 0.3"/></geometry>
        </collision>
        <inertial>
            <mass value="1"/>
            <inertia ixx="0.03" iyy="0.03" izz="0.03" ixy="0" ixz="0" iyz="0"/>
        </inertial>
    </link>

    <joint name="arm_joint3" type="revolute">
        <parent link="arm_link2"/>
        <child link="arm_link3"/>
        <origin xyz="0 0 0.4"/>
        <axis xyz="0 1 0"/>
        <limit lower="-1.57" upper="1.57"/>
    </joint>

    <!-- Wrist Pitch Joint -->
    <link name="wrist_pitch">
        <visual>
            <geometry><cylinder radius="0.05" length="0.05"/></geometry>
        </visual>
        <collision>
            <geometry><cylinder radius="0.05" length="0.05"/></geometry>
        </collision>
        <inertial>
            <mass value="0.3"/>
            <inertia ixx="0.005" iyy="0.005" izz="0.005" ixy="0" ixz="0" iyz="0"/>
        </inertial>
    </link>

    <joint name="wrist_pitch_joint" type="revolute">
        <parent link="arm_link3"/>
        <child link="wrist_pitch"/>
        <origin xyz="0 0 0.3"/>
        <axis xyz="1 0 0"/>
        <limit lower="-1.57" upper="1.57" effort="10" velocity="0.5"/>
    </joint>

    <!-- Wrist Roll Joint -->
    <link name="wrist_roll">
        <visual>
            <geometry><cylinder radius="0.05" length="0.05"/></geometry>
        </visual>
        <collision>
            <geometry><cylinder radius="0.05" length="0.05"/></geometry>
        </collision>
        <inertial>
            <mass value="0.5"/>
            <inertia ixx="0.01" iyy="0.01" izz="0.01" ixy="0" ixz="0" iyz="0"/>
        </inertial>
    </link>

    <joint name="wrist_roll_joint" type="revolute">
        <parent link="wrist_pitch"/>
        <child link="wrist_roll"/>
        <origin xyz="0 0 0"/>
        <axis xyz="0 0 1"/>
        <limit lower="-3.14" upper="3.14" effort="10" velocity="0.5"/>
    </joint>

    <!-- Gripper Palm -->
    <link name="gripper_palm">
        <visual>
            <geometry><box size="0.06 0.12 0.06"/></geometry>
        </visual>
        <collision>
            <geometry><box size="0.06 0.12 0.06"/></geometry>
        </collision>
        <inertial>
            <mass value="0.5"/>
            <inertia ixx="0.01" iyy="0.01" izz="0.01"/>
        </inertial>
    </link>

    <joint name="gripper_palm_joint" type="fixed">
        <parent link="wrist_roll"/>
        <child link="gripper_palm"/>
        <origin xyz="0 0 0.06"/>
    </joint>

    <!-- Left Finger -->
    <link name="left_finger">
        <visual>
            <geometry><box size="0.04 0.12 0.04"/></geometry>
        </visual>
        <collision>
            <geometry><box size="0.04 0.12 0.04"/></geometry>
        </collision>
        <inertial>
            <mass value="0.1"/>
            <inertia ixx="0.01" iyy="0.01" izz="0.01"/>
        </inertial>
    </link>

    <joint name="left_finger_joint" type="prismatic">
        <parent link="gripper_palm"/>
        <child link="left_finger"/>
        <origin xyz="0.02 0.035 0.02" rpy="0 0 0"/>   <!-- left -->
        <axis xyz="1 0 0"/>
        <limit lower="0" upper="0.05" effort="10" velocity="1.0"/>
    </joint>

    <!-- Right Finger -->
    <link name="right_finger">
        <visual>
            <geometry><box size="0.04 0.12 0.04"/></geometry>
        </visual>
        <collision>
            <geometry><box size="0.04 0.12 0.04"/></geometry>
        </collision>
        <inertial>
            <mass value="0.1"/>
            <inertia ixx="0.01" iyy="0.01" izz="0.01"/>
        </inertial>
    </link>

    <joint name="right_finger_joint" type="prismatic">
        <parent link="gripper_palm"/>
        <child link="right_finger"/>
        <origin xyz="-0.02 -0.035 0.02" rpy="0 0 0"/> <!-- right -->
        <axis xyz="1 0 0"/>
        <limit lower="0" upper="0.05" effort="10" velocity="1.0"/>
    </joint>

</robot>
